Workbook

Sheet Lead Waste Log
A1: FIRING RANGE WASTE & RECYCLING LOG — LEAD BULLET / TRAP WASTE
A2: Facility Name: | E2: [Enter Facility Name] | I2: Year: | J2: 2024
A4: Entry # | B4: Waste Description | C4: Accumulation Date | D4: Storage Location | E4: Drum Type / Size | F4: Weight (lbs) | G4: Shipped Date | H4: Carrier / Recycler | I4: Status | J4: Notes
A5: LED-001 | B5: Lead Bullet / Trap Waste | C5: MM/DD/YYYY | D5: [Building / Room / Bay] | E5: 55 Gallon Drum | F5: 0 | G5: N/A | H5: [Hauler Name] | I5: Pending Shipment | J5: [Optional notes]
A207: SUMMARY STATISTICS
A208: Total Drum Entries | G208: =COUNTA(A6:A205) -> 0
A209: Total Weight (lbs) | G209: =SUMIF(F6:F205,">0",F6:F205) -> 0
A210: Average Weight (lbs) | G210: =IFERROR(AVERAGEIF(F6:F205,">0",F6:F205),0) -> 0
A211: Minimum Weight (lbs) | G211: =IFERROR(minifs(F6:F205,F6:F205,">0"),0) -> 0
A212: Maximum Weight (lbs) | G212: =IFERROR(maxifs(F6:F205,F6:F205,">0"),0) -> 0
A213: Pending Shipment Count | G213: =COUNTIF(I6:I205,"Pending Shipment") -> 0
A214: Shipped Count | G214: =COUNTIF(I6:I205,"Shipped") -> 0
A215: Latest Accumulation Date | G215: =IFERROR(MAX(C6:C205),"N/A") -> 0

Sheet Copper Waste Log
A1: FIRING RANGE WASTE & RECYCLING LOG — COPPER DUST / JACKET WASTE
A2: Facility Name: | E2: [Enter Facility Name] | I2: Year: | J2: 2024
A4: Entry # | B4: Waste Description | C4: Accumulation Date | D4: Storage Location | E4: Drum Type / Size | F4: Weight (lbs) | G4: Shipped Date | H4: Carrier / Recycler | I4: Status | J4: Notes
A5: COP-001 | B5: Copper Dust / Jacket Waste | C5: MM/DD/YYYY | D5: [Building / Room / Bay] | E5: 55 Gallon Drum | F5: 0 | G5: N/A | H5: [Hauler Name] | I5: Pending Shipment | J5: [Optional notes]
A207: SUMMARY STATISTICS
A208: Total Drum Entries | G208: =COUNTA(A6:A205) -> 0
A209: Total Weight (lbs) | G209: =SUMIF(F6:F205,">0",F6:F205) -> 0
A210: Average Weight (lbs) | G210: =IFERROR(AVERAGEIF(F6:F205,">0",F6:F205),0) -> 0
A211: Minimum Weight (lbs) | G211: =IFERROR(minifs(F6:F205,F6:F205,">0"),0) -> 0
A212: Maximum Weight (lbs) | G212: =IFERROR(maxifs(F6:F205,F6:F205,">0"),0) -> 0
A213: Pending Shipment Count | G213: =COUNTIF(I6:I205,"Pending Shipment") -> 0
A214: Shipped Count | G214: =COUNTIF(I6:I205,"Shipped") -> 0
A215: Latest Accumulation Date | G215: =IFERROR(MAX(C6:C205),"N/A") -> 0

Sheet Shell Casings Log
A1: FIRING RANGE WASTE & RECYCLING LOG — SHELL CASINGS
A2: Facility Name: | E2: [Enter Facility Name] | I2: Year: | J2: 2024
A4: Entry # | B4: Waste Description | C4: Accumulation Date | D4: Storage Location | E4: Shell Metal Type | F4: Drum Type / Size | G4: Weight (lbs) | H4: Shipped Date | I4: Carrier / Recycler | J4: Status | K4: Notes
A5: SHL-001 | B5: Shell Casings | C5: MM/DD/YYYY | D5: [Building / Room / Bay] | E5: [See dropdown] | F5: 55 Gallon Drum | G5: 0 | H5: N/A | I5: [Hauler Name] | J5: Pending Shipment | K5: [Optional notes]
A207: SUMMARY STATISTICS
A208: Total Drum Entries | G208: =COUNTA(A6:A205) -> 0
A209: Total Weight (lbs) | G209: =SUMIF(G6:G205,">0",G6:G205) -> 0
A210: Average Weight (lbs) | G210: =IFERROR(AVERAGEIF(G6:G205,">0",G6:G205),0) -> 0
A211: Minimum Weight (lbs) | G211: =IFERROR(minifs(G6:G205,G6:G205,">0"),0) -> 0
A212: Maximum Weight (lbs) | G212: =IFERROR(maxifs(G6:G205,G6:G205,">0"),0) -> 0
A213: Pending Shipment Count | G213: =COUNTIF(J6:J205,"Pending Shipment") -> 0
A214: Shipped Count | G214: =COUNTIF(J6:J205,"Shipped") -> 0
A215: Latest Accumulation Date | G215: =IFERROR(MAX(C6:C205),"N/A") -> 0

Sheet Shipment Log
A1: HAZARDOUS WASTE SHIPMENT LOG — FIRING RANGE WASTE
A2: Record each off-site waste shipment. Retain a copy of the signed manifest in your EHS records file.
A3: Manifest # | B3: Waste Stream | C3: Drum / Container Qty | D3: Total Weight (lbs) | E3: Waste Code (EPA) | F3: UN Number | G3: Carrier / Hauler | H3: Disposal / Recycling Facility | I3: Shipment Date | J3: Received Date | K3: Notes / Compliance Verification
A4: [MFxxxxxx] | B4: Lead Bullet Waste | C4: 1 | D4: 1500 | E4: D008 | F4: UN3077 | G4: [Carrier Name] | H4: [Facility Name] | I4: MM/DD/YYYY | J4: MM/DD/YYYY | K4: Manifest copy filed in EHS records.

Sheet Regulatory Reference
A1: REGULATORY REFERENCE — FIRING RANGE WASTE & RECYCLING
A2: Key federal regulations governing lead/copper waste, shell casing recycling, and firing range environmental compliance. Add applicable state/local rules in the rows provided at the bottom.
A3: Agency | B3: Citation / Standard | C3: Requirement / Applicability | D3: Key Threshold / Action Level | E3: Applicability to Firing Ranges | F3: Official URL
A4: OSHA | B4: 29 CFR 1910.1025 | C4: Lead in General Industry — PEL and action level; applies to all workers handling lead bullet waste, cleaning traps, and managing lead-contaminated equipment. | D4: PEL: 50 µg/m³ TWA Action Level: 30 µg/m³ | E4: Mandatory. Includes medical surveillance, air monitoring, hygiene facilities, and training. | F4: https://www.osha.gov/laws-regs/regulations/standardnumber/1910/1910.1025
A5: OSHA | B5: 29 CFR 1910.1200 | C5: Hazard Communication Standard (HazCom/GHS) — SDS requirements, container labeling, and employee training for all hazardous waste streams. | D5: All hazardous chemicals on-site | E5: Required for labeling lead and copper waste drums; SDS access for employees. | F5: https://www.osha.gov/laws-regs/regulations/standardnumber/1910/1910.1200
A6: OSHA | B6: 29 CFR 1910.134 | C6: Respiratory Protection — required when engineering controls cannot maintain airborne lead below the PEL. | D6: When airborne lead > PEL (50 µg/m³) | E6: Respirator program required for trap cleaning, bullet sweep-up, and drum filling. | F6: https://www.osha.gov/laws-regs/regulations/standardnumber/1910/1910.134
A7: OSHA | B7: 29 CFR 1910.132–138 | C7: Personal Protective Equipment — gloves, eye/face protection, and other PPE required during all waste handling operations. | D7: Employer hazard assessment required | E7: PPE selection must address lead dust, copper dust, and sharps hazards. | F7: https://www.osha.gov/laws-regs/regulations/standardnumber/1910/1910.132
A8: EPA / RCRA | B8: 40 CFR Part 261 | C8: Identification of Hazardous Waste — lead bullet waste typically qualifies as D008 characteristic hazardous waste; copper waste may also be D008 if contaminated with lead. | D8: D008 Lead TCLP threshold: 5 mg/L | E8: Waste characterization (TCLP or process knowledge) required before first shipment. | F8: https://www.ecfr.gov/current/title-40/chapter-I/subchapter-I/part-261
A9: EPA / RCRA | B9: 40 CFR Part 262 | C9: Standards for Hazardous Waste Generators — generator status classification, manifest requirements, and accumulation time limits. | D9: VSQG: <100 kg/mo SQG: 100–1,000 kg/mo LQG: >1,000 kg/mo | E9: Determines how long waste can accumulate on-site and whether manifests are required. | F9: https://www.ecfr.gov/current/title-40/chapter-I/subchapter-I/part-262
A10: EPA / RCRA | B10: 40 CFR Part 268 | C10: Land Disposal Restrictions (LDR) — treatment standards must be met before land disposal of D008 lead waste. | D10: D008 LDR treatment standards apply | E10: Required notification to disposal facility; treatment may be required prior to land disposal. | F10: https://www.ecfr.gov/current/title-40/chapter-I/subchapter-I/part-268
A11: EPA / RCRA | B11: 40 CFR Part 273 | C11: Universal Waste Standards — may apply to brass/aluminum shell casings and other scrap metals managed for reclamation. | D11: Facilitates scrap metal recycling pathway | E11: Verify with state environmental agency whether shell casings qualify as universal waste. | F11: https://www.ecfr.gov/current/title-40/chapter-I/subchapter-I/part-273
A12: EPA | B12: SW-846 Method 1311 (TCLP) | C12: Toxicity Characteristic Leaching Procedure — determines if lead-bearing waste exhibits D008 toxicity characteristic. | D12: Lead TCLP threshold: 5 mg/L | E12: Use TCLP to characterize bullet and copper waste if process knowledge is insufficient. | F12: https://www.epa.gov/hw-sw846/sw-846-test-method-1311-toxicity-characteristic-leaching-procedure
A13: DOT | B13: 49 CFR Parts 171–180 | C13: Hazardous Materials Regulations — classification, packaging, marking, labeling, placarding, and shipping papers for off-site transport of hazardous waste. | D13: Applies to all off-site hazmat shipments | E13: Use a licensed hazmat transporter; all manifested shipments must comply. | F13: https://www.ecfr.gov/current/title-49/subtitle-B/chapter-I/subchapter-C
A14: DOT | B14: 49 CFR Part 172 | C14: Hazardous Materials Table — proper shipping names and UN numbers for lead-bearing waste. | D14: UN3077: Environmentally Hazardous Substance, Solid | E14: Use correct UN number and proper shipping name on hazardous waste manifest and packaging. | F14: https://www.ecfr.gov/current/title-49/subtitle-B/chapter-I/subchapter-C/part-172
... A18: STATE / LOCAL | B18: [Insert Citation] | C18: [Additional state/local regulation — add as needed] | D18: [Threshold or limit] | E18: [Applicability description] | F18: [URL]

Sheet Instructions
A1: FIRING RANGE WASTE & RECYCLING LOG — INSTRUCTIONS & SETUP
A2: Generic Template | No Branding | Free to Use and Distribute
A4: ABOUT THIS WORKBOOK
A5: Purpose | B5: This workbook tracks firing range waste streams including lead bullet residue, copper dust, and shell casings. It is designed for EHS professionals, range managers, and safety officers who need a simple, auditable record of waste accumulation, drum inventory, and shipment status.
A6: Waste Streams Covered | B6: • Lead Waste Log — Lead bullet core residue, sweep-up dust, and trap waste • Copper Waste Log — Copper dust and bullet jacket waste • Shell Casings Log — Brass, aluminum, steel, or other shell casings; metal type recorded per entry Each stream has its own tab with independent summary statistics.
A7: Who Should Use It | B7: Any EHS professional, range safety officer, or facility manager responsible for tracking and reporting firing range waste — at any size facility, indoor or outdoor.
A8: Cost / Licensing | B8: Free and open source. No fee, no registration, no branding requirement. Distribute and modify freely.
A10: GETTING STARTED
A11: Step 1 — Facility Info | B11: On the Dashboard tab, fill in the yellow-highlighted cells: facility name, location, department, EHS manager/POC, range identification, and report year.
A12: Step 2 — Lead Waste Log | B12: Navigate to 'Lead Waste Log'. Each time a drum or container of lead waste is staged, add a row: Entry #, Description, Accumulation Date, Storage Location, Drum Type/Size, Weight (lbs), Shipped Date, Carrier, Status, Notes. Summary statistics auto-update.
A13: Step 3 — Copper Waste Log | B13: Navigate to 'Copper Waste Log'. Log copper dust and jacket waste the same way as the Lead log. Use a consistent entry prefix (e.g., COP-001).
A14: Step 4 — Shell Casings Log | B14: Navigate to 'Shell Casings Log'. Use the 'Shell Metal Type' dropdown to designate each entry: Brass, Aluminum, Steel, Nickel-Plated Brass, Polymer, or Mixed. This replaces the former NLTA designation so the sheet works for any range.
A15: Step 5 — Shipment Log | B15: Record each off-site waste shipment: manifest number, waste stream, quantities, EPA waste codes, UN numbers, carrier, and disposal/recycling facility.
A16: Step 6 — Dashboard | B16: Review live totals from all three waste streams at a glance. Update 'Last Workbook Update' as needed.
A17: Step 7 — Regulatory Reference | B17: Review the regulatory table and add any applicable state/local rules for your jurisdiction.
A19: DATA ENTRY TIPS
A20: Entry Numbers | B20: Use a consistent prefix per stream: LED-001 for lead, COP-001 for copper, SHL-001 for shells. This ensures audit traceability across tabs.
A21: Dates | B21: Enter dates as MM/DD/YYYY. Excel stores them as date values automatically.
A22: Weights | B22: Record net weight (waste only, excluding drum tare) OR gross weight. Document your convention in the Notes column of the first entry for each stream.
A23: Status Dropdown | B23: Keep the Status field current: Pending Shipment / Shipped / Recycled / Under Review. This is the primary field reviewers check during compliance audits.
A24: Shell Metal Type | B24: The 'Shell Metal Type' dropdown on the Shell Casings Log allows mixed loads at the same facility. If a single drum contains multiple metals, select 'Mixed' and describe in the Notes column.
A26: REGULATORY NOTES
A27: Lead Waste (D008) | B27: Lead bullet waste typically qualifies as D008 characteristic hazardous waste under RCRA (40 CFR Part 261). Confirm waste characterization before first shipment. Store within EPA generator accumulation time limits.
A28: Copper Waste | B28: Copper dust and jacket fragments may also carry lead contamination. Test or apply process knowledge before characterizing as non-hazardous.
A29: Shell Casings | B29: Brass, aluminum, and steel casings are commonly managed as scrap metal for recycling. Confirm with your state agency whether universal waste rules (40 CFR Part 273) apply.
A30: Generator Status | B30: VSQG (<100 kg/month), SQG (100–1,000 kg/month), or LQG (>1,000 kg/month) status governs accumulation times and manifest requirements. See the Regulatory Reference tab.
A32: FEEDBACK
A33: Contributing | B33: This is a community resource. If you find errors, outdated regulations, or have improvements, consider sharing feedback with the source repository maintainers.

Sheet Dashboard
B1: FIRING RANGE WASTE & RECYCLING — DASHBOARD
B2: Live summary pulled from Lead Waste Log, Copper Waste Log, and Shell Casings Log
B4: FACILITY INFORMATION
B5: Facility / Installation Name: | E5: [Enter Facility Name]
B6: Location / Address: | E6: [City, State, ZIP]
B7: Responsible Department: | E7: [e.g., Environmental & Safety]
B8: EHS Manager / POC: | E8: [Name and Title]
B9: Range Identification: | E9: [e.g., Indoor Range A, Outdoor Range 1]
B10: Report / Log Year: | E10: 2024
B11: Last Workbook Update: | E11: [MM/DD/YYYY]
B13: LEAD BULLET / TRAP WASTE
B14: Total Drum Entries | F14: ='Lead Waste Log'!E207 -> 0
B15: Total Weight (lbs) | F15: ='Lead Waste Log'!E208 -> 0
B16: Average Weight (lbs) | F16: ='Lead Waste Log'!E209 -> 0
B17: Minimum Weight (lbs) | F17: ='Lead Waste Log'!E210 -> 0
B18: Maximum Weight (lbs) | F18: ='Lead Waste Log'!E211 -> 0
B19: Pending Shipment Count | F19: ='Lead Waste Log'!E212 -> 0
B20: Shipped Count | F20: ='Lead Waste Log'!E213 -> 0
B21: Latest Accumulation Date | F21: ='Lead Waste Log'!E214 -> 0
B24: COPPER DUST / JACKET WASTE
B25: Total Drum Entries | F25: ='Copper Waste Log'!E207 -> 0
B26: Total Weight (lbs) | F26: ='Copper Waste Log'!E208 -> 0
B27: Average Weight (lbs) | F27: ='Copper Waste Log'!E209 -> 0
B28: Minimum Weight (lbs) | F28: ='Copper Waste Log'!E210 -> 0
B29: Maximum Weight (lbs) | F29: ='Copper Waste Log'!E211 -> 0
B30: Pending Shipment Count | F30: ='Copper Waste Log'!E212 -> 0
B31: Shipped Count | F31: ='Copper Waste Log'!E213 -> 0
B32: Latest Accumulation Date | F32: ='Copper Waste Log'!E214 -> 0
B35: SHELL CASINGS (ALL METALS)
B36: Total Drum Entries | F36: ='Shell Casings Log'!G207 -> 0
B37: Total Weight (lbs) | F37: ='Shell Casings Log'!G208 -> 0
B38: Average Weight (lbs) | F38: ='Shell Casings Log'!G209 -> 0
B39: Minimum Weight (lbs) | F39: ='Shell Casings Log'!G210 -> 0
B40: Maximum Weight (lbs) | F40: ='Shell Casings Log'!G211 -> 0
B41: Pending Shipment Count | F41: ='Shell Casings Log'!G212 -> 0
B42: Shipped Count | F42: ='Shell Casings Log'!G213 -> 0
B43: Latest Accumulation Date | F43: ='Shell Casings Log'!G214 -> 0
B46: COMBINED TOTALS — ALL WASTE STREAMS
B47: Combined Total Weight (lbs) | F47: ='Lead Waste Log'!E208+'Copper Waste Log'!E208+'Shell Casings Log'!G208 -> 0
B48: Combined Drum / Container Count | F48: ='Lead Waste Log'!E207+'Copper Waste Log'!E207+'Shell Casings Log'!G207 -> 0
...
